Workbook

Sheet 01 Dashboard
B1: Steuerplanung Familie – Kanton Zürich
B2: ="Steuerjahr "&'02 Eingaben'!$C$7&" · Ehepaar mit "&'02 Eingaben'!$C$9&" Kindern · Planungsstand: erwartetes steuerbares Einkommen, Zielwert, Vorsorge und Miete" -> Steuerjahr 2026 · Ehepaar mit 3 Kindern · Planungsstand: erwartetes steuerbares Einkommen, Zielwert, Vorsorge und Miete
B3: =IF('05 Berechnung'!$C$118>0,"● "&'05 Berechnung'!$C$118&" FEHLER – Ergebnis nicht verlässlich (siehe Prüfungen unten)",IF('05 Berechnung'!$C$119>0,"● "&'05 Berechnung'!$C$119&" Warnung(en) – siehe unten",IF('05 Berechnung'!$C$120>0,"● Keine Warnungen – "&'05 Berechnung'!$C$120&" Hinweis(e) unten","● Alle Plausibilitätsprüfungen bestanden"))) -> ● Keine Warnungen – 1 Hinweis(e) unten
B5: Die 7 Kernfragen auf einen Blick
B6: Frage | C6: Heute (Szenario A) | D6: Mit Empfehlung (Szenario C) | E6: Kommentar
B7: 1 Erwartetes steuerbares Einkommen (Kanton/Gemeinde) | C7: ='05 Berechnung'!$C$75 -> 177400 | D7: ='05 Berechnung'!$E$75 -> 160000 | E7: ="Vor Vorsorge-Optimierung: CHF "&FIXED('05 Berechnung'!$C$52,0) -> Vor Vorsorge-Optimierung: CHF 180,400
B8: 2 Steuerbares Einkommen Vorjahr (Referenzjahr) | C8: ='05 Berechnung'!$C$57 -> 165000 | D8: ='05 Berechnung'!$C$57 -> 165000 | E8: ="Referenzjahr "&'05 Berechnung'!$C$55 -> Referenzjahr 2025
B9: 3 Differenz zum Zielwert (+ = über Ziel) | C9: ='05 Berechnung'!$C$78 -> 17400 | D9: ='05 Berechnung'!$E$78 -> 0 | E9: ="Zielwert: CHF "&FIXED('05 Berechnung'!$C$62,0) -> Zielwert: CHF 160,000
B10: 4 Säule 3a: verbleibendes Potenzial / empfohlene Einzahlung | C10: ='05 Berechnung'!$C$16+'05 Berechnung'!$D$16 -> 11516 | D10: ='03 Optimierung'!$D$33+'03 Optimierung'!$D$34 -> 11516 | E10: ="Empfehlung Ehemann CHF "&FIXED('03 Optimierung'!$D$33,0)&" · Ehefrau CHF "&FIXED('03 Optimierung'!$D$34,0) -> Empfehlung Ehemann CHF 4,258 · Ehefrau CHF 7,258
B11: 5 Zusätzlicher PK-Einkauf zum Erreichen des Zielwerts (nur steuerlicher Effekt) | C11: =0 -> 0 | D11: ='03 Optimierung'!$D$35+'03 Optimierung'!$D$36 -> 5884 | E11: ="Nur möglich bei Einkaufspotenzial lt. Vorsorgeausweis!" -> Nur möglich bei Einkaufspotenzial lt. Vorsorgeausweis!
B12: 6 Mietstufe und Monatsmiete | C12: ="Stufe "&'05 Berechnung'!$C$81&" · CHF "&FIXED('05 Berechnung'!$C$82,0) -> Stufe 5 · CHF 2,700 | D12: ="Stufe "&'05 Berechnung'!$E$81&" · CHF "&FIXED('05 Berechnung'!$E$82,0) -> Stufe 4 · CHF 2,500 | E12: ="Mietänderung p. a.: CHF "&FIXED('05 Berechnung'!$E$84,0)&" (– = günstiger)" -> Mietänderung p. a.: CHF -2,400 (– = günstiger)
B13: 7 Kombinierter Effekt Steuer + Miete p. a. (gegenüber A) | C13: =0 -> 0 | D13: ='05 Berechnung'!$E$89 -> 7272 | E13: ="Steuer ca. CHF "&FIXED('05 Berechnung'!$E$86,0)&" + Miete CHF "&FIXED('05 Berechnung'!$C$83-'05 Berechnung'!$E$83,0) -> Steuer ca. CHF 4,872 + Miete CHF 2,400
B15: Szenariovergleich
B16: Kennzahl (CHF) | C16: A – Keine zusätzliche Optimierung | D16: B – Säule 3a optimiert | E16: C – Zielwert erreichen | F16: D – Frei definierbar
B17: Steuerbares Einkommen (Kanton/Gemeinde) | C17: ='05 Berechnung'!$C$75 -> 177400 | D17: ='05 Berechnung'!$D$75 -> 165884 | E17: ='05 Berechnung'!$E$75 -> 160000 | F17: ='05 Berechnung'!$F$75 -> 160884
B18: Zielwert | C18: ='05 Berechnung'!$C$62 -> 160000 | D18: ='05 Berechnung'!$C$62 -> 160000 | E18: ='05 Berechnung'!$C$62 -> 160000 | F18: ='05 Berechnung'!$C$62 -> 160000
B19: Steuerbares Einkommen Vorjahr | C19: ='05 Berechnung'!$C$57 -> 165000 | D19: ='05 Berechnung'!$C$57 -> 165000 | E19: ='05 Berechnung'!$C$57 -> 165000 | F19: ='05 Berechnung'!$C$57 -> 165000
B20: Veränderung gegenüber Vorjahr | C20: ='05 Berechnung'!$C$77 -> 12400 | D20: ='05 Berechnung'!$D$77 -> 884 | E20: ='05 Berechnung'!$E$77 -> -5000 | F20: ='05 Berechnung'!$F$77 -> -4116
B21: Abweichung zum Zielwert | C21: ='05 Berechnung'!$C$78 -> 17400 | D21: ='05 Berechnung'!$D$78 -> 5884 | E21: ='05 Berechnung'!$E$78 -> 0 | F21: ='05 Berechnung'!$F$78 -> 884
B22: Zielwert erreicht? | C22: ='05 Berechnung'!$C$79 -> Nein | D22: ='05 Berechnung'!$D$79 -> Nein | E22: ='05 Berechnung'!$E$79 -> Ja | F22: ='05 Berechnung'!$F$79 -> Nein
B23: Säule 3a gesamt | C23: ='05 Berechnung'!$C$71 -> 3000 | D23: ='05 Berechnung'!$D$71 -> 14516 | E23: ='05 Berechnung'!$E$71 -> 14516 | F23: ='05 Berechnung'!$F$71 -> 14516
B24: PK-Einkäufe gesamt | C24: ='05 Berechnung'!$C$72 -> 0 | D24: ='05 Berechnung'!$D$72 -> 0 | E24: ='05 Berechnung'!$E$72 -> 5884 | F24: ='05 Berechnung'!$F$72 -> 5000
B25: Vorsorgeeinzahlungen gesamt | C25: ='05 Berechnung'!$C$73 -> 3000 | D25: ='05 Berechnung'!$D$73 -> 14516 | E25: ='05 Berechnung'!$E$73 -> 20400 | F25: ='05 Berechnung'!$F$73 -> 19516
B26: Zusätzliche Vorsorge gegenüber A | C26: ='05 Berechnung'!$C$74 -> 0 | D26: ='05 Berechnung'!$D$74 -> 11516 | E26: ='05 Berechnung'!$E$74 -> 17400 | F26: ='05 Berechnung'!$F$74 -> 16516
B27: Geschätzte Steuerbelastung (Näherung) | C27: ='05 Berechnung'!$C$88 -> 34472 | D27: ='05 Berechnung'!$D$88 -> 31247.52 | E27: ='05 Berechnung'!$E$88 -> 29600 | F27: ='05 Berechnung'!$F$88 -> 29847.52
B28: Geschätzte Steuerersparnis gegenüber A | C28: ='05 Berechnung'!$C$86 -> 0 | D28: ='05 Berechnung'!$D$86 -> 3224.48 | E28: ='05 Berechnung'!$E$86 -> 4872 | F28: ='05 Berechnung'!$F$86 -> 4624.48
B29: Mietstufe (Nr.) | C29: ='05 Berechnung'!$C$81 -> 5 | D29: ='05 Berechnung'!$D$81 -> 5 | E29: ='05 Berechnung'!$E$81 -> 4 | F29: ='05 Berechnung'!$F$81 -> 5
B30: Jahresmiete | C30: ='05 Berechnung'!$C$83 -> 32400 | D30: ='05 Berechnung'!$D$83 -> 32400 | E30: ='05 Berechnung'!$E$83 -> 30000 | F30: ='05 Berechnung'!$F$83 -> 32400
B31: Veränderung Miete p. a. gegenüber A (– = günstiger) | C31: ='05 Berechnung'!$C$84 -> 0 | D31: ='05 Berechnung'!$D$84 -> 0 | E31: ='05 Berechnung'!$E$84 -> -2400 | F31: ='05 Berechnung'!$F$84 -> 0
B32: Kombinierter finanzieller Vorteil gegenüber A (Steuer + Miete) | C32: ='05 Berechnung'!$C$89 -> 0 | D32: ='05 Berechnung'!$D$89 -> 3224.48 | E32: ='05 Berechnung'!$E$89 -> 7272 | F32: ='05 Berechnung'!$F$89 -> 4624.48
B34: Warnungen und Hinweise (automatisch)
B35: =IFERROR(INDEX('05 Berechnung'!$B$94:$B$116,MATCH(1,'05 Berechnung'!$F$94:$F$116,0)),"") -> Grundlagen verifiziert | C35: =IFERROR(INDEX('05 Berechnung'!$C$94:$C$116,MATCH(1,'05 Berechnung'!$F$94:$F$116,0)),"") -> HINWEIS | D35: =IFERROR(INDEX('05 Berechnung'!$G$94:$G$116,MATCH(1,'05 Berechnung'!$F$94:$F$116,0)),"") -> 24 verwendete Parameter sind in 06 Grundlagen mit «prüfen»/«unsicher» markiert – bitte gegen die offizielle Wegleitung verifizieren.
B36: =IFERROR(INDEX('05 Berechnung'!$B$94:$B$116,MATCH(2,'05 Berechnung'!$F$94:$F$116,0)),"") | C36: =IFERROR(INDEX('05 Berechnung'!$C$94:$C$116,MATCH(2,'05 Berechnung'!$F$94:$F$116,0)),"") | D36: =IFERROR(INDEX('05 Berechnung'!$G$94:$G$116,MATCH(2,'05 Berechnung'!$F$94:$F$116,0)),"")
B37: =IFERROR(INDEX('05 Berechnung'!$B$94:$B$116,MATCH(3,'05 Berechnung'!$F$94:$F$116,0)),"") | C37: =IFERROR(INDEX('05 Berechnung'!$C$94:$C$116,MATCH(3,'05 Berechnung'!$F$94:$F$116,0)),"") | D37: =IFERROR(INDEX('05 Berechnung'!$G$94:$G$116,MATCH(3,'05 Berechnung'!$F$94:$F$116,0)),"")
B38: =IFERROR(INDEX('05 Berechnung'!$B$94:$B$116,MATCH(4,'05 Berechnung'!$F$94:$F$116,0)),"") | C38: =IFERROR(INDEX('05 Berechnung'!$C$94:$C$116,MATCH(4,'05 Berechnung'!$F$94:$F$116,0)),"") | D38: =IFERROR(INDEX('05 Berechnung'!$G$94:$G$116,MATCH(4,'05 Berechnung'!$F$94:$F$116,0)),"")
B39: =IFERROR(INDEX('05 Berechnung'!$B$94:$B$116,MATCH(5,'05 Berechnung'!$F$94:$F$116,0)),"") | C39: =IFERROR(INDEX('05 Berechnung'!$C$94:$C$116,MATCH(5,'05 Berechnung'!$F$94:$F$116,0)),"") | D39: =IFERROR(INDEX('05 Berechnung'!$G$94:$G$116,MATCH(5,'05 Berechnung'!$F$94:$F$116,0)),"")
B40: =IFERROR(INDEX('05 Berechnung'!$B$94:$B$116,MATCH(6,'05 Berechnung'!$F$94:$F$116,0)),"") | C40: =IFERROR(INDEX('05 Berechnung'!$C$94:$C$116,MATCH(6,'05 Berechnung'!$F$94:$F$116,0)),"") | D40: =IFERROR(INDEX('05 Berechnung'!$G$94:$G$116,MATCH(6,'05 Berechnung'!$F$94:$F$116,0)),"")
B41: =IFERROR(INDEX('05 Berechnung'!$B$94:$B$116,MATCH(7,'05 Berechnung'!$F$94:$F$116,0)),"") | C41: =IFERROR(INDEX('05 Berechnung'!$C$94:$C$116,MATCH(7,'05 Berechnung'!$F$94:$F$116,0)),"") | D41: =IFERROR(INDEX('05 Berechnung'!$G$94:$G$116,MATCH(7,'05 Berechnung'!$F$94:$F$116,0)),"")
B42: =IFERROR(INDEX('05 Berechnung'!$B$94:$B$116,MATCH(8,'05 Berechnung'!$F$94:$F$116,0)),"") | C42: =IFERROR(INDEX('05 Berechnung'!$C$94:$C$116,MATCH(8,'05 Berechnung'!$F$94:$F$116,0)),"") | D42: =IFERROR(INDEX('05 Berechnung'!$G$94:$G$116,MATCH(8,'05 Berechnung'!$F$94:$F$116,0)),"")
B43: Es werden maximal 8 Meldungen angezeigt; vollständige Liste in 05 Berechnung, Abschnitt 8.
...

Sheet 02 Eingaben
B1: 02 Eingaben – Einkommen, Familie, Abzüge, Vorsorge, Ziel
B2: Nur gelbe und orange Zellen werden bearbeitet. Alle Beispielwerte sind Platzhalter und müssen durch Ihre Zahlen ersetzt werden.
B4: Legende: | C4: Eingabe | D4: Optional/Überschreiben | E4: Berechnet | F4: Berechnete Zellen sind blattgeschützt (Schutz ohne Passwort aufhebbar: Überprüfen → Blattschutz aufheben).
B6: 1 Allgemeines
B7: Steuerjahr (Planungsjahr) | C7: 2026 | I7: Bestimmt die verwendete Spalte in 06 Grundlagen.
B8: Zivilstand | C8: Verheiratet | I8: Das Modell ist für gemeinsam veranlagte Ehepaare ausgelegt.
B9: Anzahl Kinder | C9: 3
B10: davon mit Anspruch auf Kinderabzug | C10: 3 | I10: Minderjährige Kinder sowie Kinder in Erstausbildung (Details: Wegleitung ZH, Ziff. Kinderabzug).
B11: Wohngemeinde (nur Information) | C11: Zürich
B13: 2 Einkommen (gemäss Lohnausweis)
C14: Ehemann | D14: Ehefrau | E14: Gemeinsam | F14: Total
B15: Bruttolohn (Lohnausweis Ziff. 8) | C15: 200000 | D15: 70000 | F15: =SUM(C15:E15) -> 270000 | I15: Inkl. Bonus, wenn dieser in Ziff. 8 enthalten ist.
B16: Bonus / variable Vergütung (nur zusätzlich, falls nicht in Ziff. 8) | C16: 0 | D16: 0 | F16: =SUM(C16:E16) -> 0
B17: AHV/IV/EO/ALV/NBU-Beiträge (Ziff. 9, positiv eingeben) | C17: 13000 | D17: 4700 | F17: =SUM(C17:E17) -> 17700
B18: BVG-Beiträge ordentlich (Ziff. 10.1, positiv eingeben) | C18: 14000 | D18: 3500 | F18: =SUM(C18:E18) -> 17500 | I18: Ordentliche Beiträge sind bereits im Lohnausweis abgezogen. Freiwillige Einkäufe NICHT hier erfassen.
B19: Nettolohn berechnet (entspricht Ziff. 11) | C19: =C15+C16-C17-C18 -> 173000 | D19: =D15+D16-D17-D18 -> 61800 | F19: =C19+D19 -> 234800
B20: Nettolohn manuell (optional – überschreibt die Berechnung) | F20: =SUM(C20:D20) -> 0 | I20: Nur ausfüllen, wenn Ziff. 11 des Lohnausweises vom berechneten Wert abweicht.
B21: Massgebender Nettolohn | C21: =IF(C20<>"",C20,C19) -> 173000 | D21: =IF(D20<>"",D20,D19) -> 61800 | F21: =C21+D21 -> 234800
B22: Weitere Erwerbseinkommen (Nebenerwerb, netto) | C22: 0 | D22: 0 | F22: =SUM(C22:E22) -> 0
B23: Weitere steuerbare Einkünfte (Renten, Wertschriften, Liegenschaften, netto) | C23: 0 | D23: 0 | E23: 0 | F23: =SUM(C23:E23) -> 0 | I23: Nach Abzug der damit zusammenhängenden Kosten (z. B. Schuldzinsen separat unter «Weitere Abzüge»).
B24: Total steuerbare Einkünfte | C24: =C21+C22+C23 -> 173000 | D24: =D21+D22+D23 -> 61800 | E24: =E23 -> 0 | F24: =SUM(C24:E24) -> 234800
B26: 3 Berufsauslagen – Angaben
C27: Ehemann | D27: Ehefrau
B28: Fahrkosten Arbeitsweg effektiv (günstigstes Verkehrsmittel, CHF/Jahr) | C28: 1800 | D28: 800 | I28: Wird auf den Maximalbetrag gemäss 06 Grundlagen begrenzt (Kanton und Bund getrennt).
B29: Arbeitstage mit auswärtiger Verpflegung (Anzahl) | C29: 100 | D29: 0
B30: Übrige Berufsauslagen effektiv (nur wenn höher als Pauschale und belegt) | I30: Leer = Pauschale (3 % des Nettolohns, Min./Max. lt. Grundlagen).
B32: 4 Abzüge (ohne Säule 3a / PK-Einkauf)
B33: Effektiv bezahlte Versicherungsprämien/Sparzinsen (z. B. Krankenkasse, CHF/Jahr) | C33: 14000 | I33: Leer = Maximalabzug wird angenommen. Abzug = tieferer Wert aus effektiv und Maximum.
B34: Abzugsposition | C34: Automatisch Kanton | D34: Manuell Kanton (optional) | E34: Automatisch Bund | F34: Manuell Bund (optional) | G34: VERWENDET Kanton | H34: VERWENDET Bund | I34: Hinweis
B35: Berufsauslagen Ehemann | C35: ='05 Berechnung'!$C$29 -> 7300 | E35: ='05 Berechnung'!$E$29 -> 7300 | G35: =IF(D35<>"",D35,C35) -> 7300 | H35: =IF(F35<>"",F35,E35) -> 7300 | I35: Fahrkosten + Verpflegung + übrige (Pauschale).
B36: Berufsauslagen Ehefrau | C36: ='05 Berechnung'!$D$29 -> 2800 | E36: ='05 Berechnung'!$F$29 -> 2800 | G36: =IF(D36<>"",D36,C36) -> 2800 | H36: =IF(F36<>"",F36,E36) -> 2800
B37: Versicherungsprämien und Sparzinsen | C37: ='05 Berechnung'!$C$34 -> 9700 | E37: ='05 Berechnung'!$D$34 -> 5800 | G37: =IF(D37<>"",D37,C37) -> 9700 | H37: =IF(F37<>"",F37,E37) -> 5800 | I37: Ehepaar mit Vorsorgebeiträgen + Zuschlag je Kind.
B38: Kinderabzug | C38: ='05 Berechnung'!$C$35 -> 28200 | E38: ='05 Berechnung'!$D$35 -> 20400 | G38: =IF(D38<>"",D38,C38) -> 28200 | H38: =IF(F38<>"",F38,E38) -> 20400 | I38: Anzahl Kinder mit Abzug × Betrag pro Kind.
B39: Zweiverdienerabzug | C39: ='05 Berechnung'!$C$37 -> 5900 | E39: ='05 Berechnung'!$D$37 -> 14100 | G39: =IF(D39<>"",D39,C39) -> 5900 | H39: =IF(F39<>"",F39,E39) -> 14100 | I39: Nur wenn beide Ehegatten erwerbstätig sind. Regel für ZH unsicher → ggf. manuell überschreiben.
B40: Verheiratetenabzug (nur direkte Bundessteuer) | C40: ='05 Berechnung'!$C$38 -> 0 | E40: ='05 Berechnung'!$D$38 -> 2800 | G40: =IF(D40<>"",D40,C40) -> 0 | H40: =IF(F40<>"",F40,E40) -> 2800 | I40: Im Kanton Zürich nicht anwendbar (Kanton: 0).
B41: Fremdbetreuungskosten der Kinder (manuell, gemäss Wegleitung begrenzt) | C41: – | D41: 0 | E41: – | G41: =N(D41) -> 0 | H41: =IF(F41<>"",F41,N(D41)) -> 0 | I41: Höchstbeträge Kanton/Bund bitte in der Wegleitung prüfen.
B42: Weiterer Abzug 1: Spenden | C42: – | D42: 500 | E42: – | G42: =N(D42) -> 500 | H42: =IF(F42<>"",F42,N(D42)) -> 500 | I42: Beispiel; Bezeichnung in Spalte B frei änderbar.
B43: Weiterer Abzug 2: (Bezeichnung) | C43: – | D43: 0 | E43: – | G43: =N(D43) -> 0 | H43: =IF(F43<>"",F43,N(D43)) -> 0 | I43: z. B. Schuldzinsen, Krankheitskosten über Selbstbehalt, Weiterbildung.
B44: Weiterer Abzug 3: (Bezeichnung) | C44: – | D44: 0 | E44: – | G44: =N(D44) -> 0 | H44: =IF(F44<>"",F44,N(D44)) -> 0
B45: Total Abzüge (ohne 3a/PK) | G45: =SUM(G35:G44) -> 54400 | H45: =SUM(H35:H44) -> 53700 | I45: Bei manuellen Abzügen ohne Bund-Wert wird der Kantonswert auch für den Bund verwendet.
...

Sheet 03 Optimierung
B1: 03 Optimierung – Simulation von Säule 3a und PK-Einkäufen
B2: Gelbe Zellen sind Eingaben (Priorität, Szenario D). Alles andere wird berechnet.
B3: WICHTIG: PK-Einkäufe werden nur hinsichtlich ihres steuerlichen Effekts modelliert. Ein tatsächlicher Einkauf ist nur möglich, soweit gemäss persönlichem Vorsorgeausweis ein Einkaufspotenzial besteht (Reglement der Pensionskasse beachten; nach Einkauf 3 Jahre Sperrfrist für Kapitalbezüge, Art. 79b Abs. 3 BVG).
B5: 1 Ausgangslage (Kanton/Gemeinde)
B6: Steuerbares Einkommen ohne jede 3a-/PK-Einzahlung | C6: ='05 Berechnung'!$C$52 -> 180400
B7: – bereits geleistete/geplante Vorsorgezahlungen (3a + PK, Szenario A) | C7: ='05 Berechnung'!$C$73 -> 3000
B8: Erwartetes steuerbares Einkommen vor zusätzlichen Einzahlungen (Szenario A) | C8: ='05 Berechnung'!$C$75 -> 177400
B9: Zielwert | C9: ='05 Berechnung'!$C$62 -> 160000
B10: Differenz zum Zielwert (+ = über Ziel, Einzahlungen nötig) | C10: =C8-C9 -> 17400
B11: Steuerbares Einkommen Vorjahr | C11: ='05 Berechnung'!$C$57 -> 165000
B12: Status | D12: =IF(C10<=0,"Der Zielwert ist bereits ohne weitere Einzahlung erreicht.","Das Einkommen liegt CHF "&FIXED(C10,0)&" über dem Zielwert – zusätzliche Einzahlungen nötig.") -> Das Einkommen liegt CHF 17,400 über dem Zielwert – zusätzliche Einzahlungen nötig.
B14: 2 Instrumente und Priorität (Reihenfolge anpassbar: 1 = zuerst)
B15: Instrument | C15: Priorität (1–4) | D15: Bereits geplant (A) | E15: Maximum / Potenzial total | F15: Verbleibendes Potenzial | H15: Hinweis
B16: Säule 3a Ehemann | C16: 1 | D16: ='05 Berechnung'!$C$15 -> 3000 | E16: ='05 Berechnung'!$C$14 -> 7258 | F16: ='05 Berechnung'!$C$16 -> 4258 | H16: Standard: 3a Ehemann, 3a Ehefrau, dann PK-Einkauf.
B17: Säule 3a Ehefrau | C17: 2 | D17: ='05 Berechnung'!$D$15 -> 0 | E17: ='05 Berechnung'!$D$14 -> 7258 | F17: ='05 Berechnung'!$D$16 -> 7258
B18: PK-Einkauf Ehemann | C18: 3 | D18: ='05 Berechnung'!$C$19 -> 0 | E18: =IF('05 Berechnung'!$C$17=1,'05 Berechnung'!$C$18,"nicht erfasst") -> 40000 | F18: ='05 Berechnung'!$C$20 -> 40000 | H18: Potenzial lt. Vorsorgeausweis (02 Eingaben).
B19: PK-Einkauf Ehefrau | C19: 4 | D19: ='05 Berechnung'!$D$19 -> 0 | E19: =IF('05 Berechnung'!$D$17=1,'05 Berechnung'!$D$18,"nicht erfasst") -> 15000 | F19: ='05 Berechnung'!$D$20 -> 15000
B20: Prüfung Prioritäten (1–4 je genau einmal) | C20: =IF(AND(COUNTIF(C16:C19,1)=1,COUNTIF(C16:C19,2)=1,COUNTIF(C16:C19,3)=1,COUNTIF(C16:C19,4)=1),"OK","Fehler") -> OK
B22: 3 Zuteilung nach Priorität (Szenario C – Zielwert erreichen)
B23: Schritt | C23: Instrument | D23: Verbleibendes Potenzial | E23: Noch benötigt (vorher) | F23: Zusätzliche Einzahlung | G23: Noch offen (nachher)
B24: 1 | C24: =IFERROR(INDEX($B$16:$B$19,MATCH(B24,$C$16:$C$19,0)),"–") -> Säule 3a Ehemann | D24: =IFERROR(INDEX($F$16:$F$19,MATCH(B24,$C$16:$C$19,0)),0) -> 4258 | E24: =MAX(0,$C$10) -> 17400 | F24: =MIN(D24,E24) -> 4258 | G24: =E24-F24 -> 13142
B25: 2 | C25: =IFERROR(INDEX($B$16:$B$19,MATCH(B25,$C$16:$C$19,0)),"–") -> Säule 3a Ehefrau | D25: =IFERROR(INDEX($F$16:$F$19,MATCH(B25,$C$16:$C$19,0)),0) -> 7258 | E25: =G24 -> 13142 | F25: =MIN(D25,E25) -> 7258 | G25: =E25-F25 -> 5884
B26: 3 | C26: =IFERROR(INDEX($B$16:$B$19,MATCH(B26,$C$16:$C$19,0)),"–") -> PK-Einkauf Ehemann | D26: =IFERROR(INDEX($F$16:$F$19,MATCH(B26,$C$16:$C$19,0)),0) -> 40000 | E26: =G25 -> 5884 | F26: =MIN(D26,E26) -> 5884 | G26: =E26-F26 -> 0
B27: 4 | C27: =IFERROR(INDEX($B$16:$B$19,MATCH(B27,$C$16:$C$19,0)),"–") -> PK-Einkauf Ehefrau | D27: =IFERROR(INDEX($F$16:$F$19,MATCH(B27,$C$16:$C$19,0)),0) -> 15000 | E27: =G26 -> 0 | F27: =MIN(D27,E27) -> 0 | G27: =E27-F27 -> 0
B28: Total zusätzliche Einzahlungen | F28: =SUM(F24:F27) -> 17400
B29: Rest, der nicht erreichbar ist (Potenzial erschöpft) | G29: =G27 -> 0
B31: 4 Ergebnis Szenario C – Aufteilung je Instrument
B32: Instrument | C32: Bereits geplant (A) | D32: Zusätzlich (C) | E32: Total Szenario C | F32: Maximum / Potenzial | G32: Status
B33: Säule 3a Ehemann | C33: =D16 -> 3000 | D33: =IFERROR(INDEX($F$24:$F$27,$C16),0) -> 4258 | E33: =C33+D33 -> 7258 | F33: =E16 -> 7258 | G33: =IF(E33>F33+0.5,"über Maximum","OK") -> OK
B34: Säule 3a Ehefrau | C34: =D17 -> 0 | D34: =IFERROR(INDEX($F$24:$F$27,$C17),0) -> 7258 | E34: =C34+D34 -> 7258 | F34: =E17 -> 7258 | G34: =IF(E34>F34+0.5,"über Maximum","OK") -> OK
B35: PK-Einkauf Ehemann | C35: =D18 -> 0 | D35: =IFERROR(INDEX($F$24:$F$27,$C18),0) -> 5884 | E35: =C35+D35 -> 5884 | F35: =E18 -> 40000 | G35: =IF('05 Berechnung'!$C$17=0,IF(E35>0,"Potenzial nicht erfasst","–"),IF(E35>'05 Berechnung'!$C$18+0.5,"über Potenzial","OK")) -> OK
B36: PK-Einkauf Ehefrau | C36: =D19 -> 0 | D36: =IFERROR(INDEX($F$24:$F$27,$C19),0) -> 0 | E36: =C36+D36 -> 0 | F36: =E19 -> 15000 | G36: =IF('05 Berechnung'!$D$17=0,IF(E36>0,"Potenzial nicht erfasst","–"),IF(E36>'05 Berechnung'!$D$18+0.5,"über Potenzial","OK")) -> OK
B37: Total | C37: =SUM(C33:C36) -> 3000 | D37: =SUM(D33:D36) -> 17400 | E37: =SUM(E33:E36) -> 20400 | F37: ='05 Berechnung'!$E$75 -> 160000 | G37: ← Steuerbares Einkommen C
B39: 5 Szenario B – Säule 3a optimiert (zusätzliche 3a-Einzahlungen)
B40: Instrument | C40: Zusätzlich (B) | D40: Total (B) | E40: 3a-Maximum
B41: Säule 3a Ehemann – zusätzlich | C41: =MIN($F$16,IF('02 Eingaben'!$C$63="Ja",MAX(0,$C$10),1000000000)) -> 4258 | D41: =D16+C41 -> 7258 | E41: =E16 -> 7258
B42: Säule 3a Ehefrau – zusätzlich | C42: =MIN($F$17,IF('02 Eingaben'!$C$63="Ja",MAX(0,$C$10),1000000000)-C41) -> 7258 | D42: =D17+C42 -> 7258 | E42: =E17 -> 7258
B43: Szenario B schöpft das verbleibende 3a-Potenzial aus (bzw. nur bis zum Zielwert, falls in 02 Eingaben «Szenario B: nur bis Zielwert» = Ja). PK-Einkäufe bleiben wie in Szenario A.
B45: 6 Szenario D – frei definierbar (Beträge insgesamt im Steuerjahr, inkl. bereits geplanter)
B46: Instrument | C46: Betrag Szenario D | D46: Maximum / Potenzial | E46: Status
...

Sheet 04 Mietmodell
B1: 04 Mietmodell – einkommensabhängige Miete
B2: Stufen aufsteigend und lückenlos von oben erfassen. «bis» ist inklusive (Einkommen ≤ Grenze = diese Stufe).
B5: 1 Mietstufen (Eingabe)
B6: Beispielwerte – bitte durch die Stufen gemäss Ihrem Mietvertrag/Reglement ersetzen. Nicht benötigte Zeilen leer lassen.
B7: Stufe | C7: Steuerbares Einkommen bis (CHF) | D7: Monatsmiete (CHF) | E7: Jahresmiete (berechnet) | F7: Prüfung
B8: Stufe 1 | C8: 100000 | D8: 1900 | E8: =IF(D8="","",D8*12) -> 22800 | F8: =IF(AND(C8="",D8=""),"leer",IF(OR(C8="",D8=""),"unvollständig","OK")) -> OK
B9: Stufe 2 | C9: 120000 | D9: 2100 | E9: =IF(D9="","",D9*12) -> 25200 | F9: =IF(AND(C9="",D9=""),"leer",IF(OR(C9="",D9=""),"unvollständig",IF(C8="","Lücke",IF(C9<=C8,"nicht aufsteigend","OK")))) -> OK
B10: Stufe 3 | C10: 140000 | D10: 2300 | E10: =IF(D10="","",D10*12) -> 27600 | F10: =IF(AND(C10="",D10=""),"leer",IF(OR(C10="",D10=""),"unvollständig",IF(C9="","Lücke",IF(C10<=C9,"nicht aufsteigend","OK")))) -> OK
B11: Stufe 4 | C11: 160000 | D11: 2500 | E11: =IF(D11="","",D11*12) -> 30000 | F11: =IF(AND(C11="",D11=""),"leer",IF(OR(C11="",D11=""),"unvollständig",IF(C10="","Lücke",IF(C11<=C10,"nicht aufsteigend","OK")))) -> OK
B12: Stufe 5 | C12: 180000 | D12: 2700 | E12: =IF(D12="","",D12*12) -> 32400 | F12: =IF(AND(C12="",D12=""),"leer",IF(OR(C12="",D12=""),"unvollständig",IF(C11="","Lücke",IF(C12<=C11,"nicht aufsteigend","OK")))) -> OK
B13: Stufe 6 | C13: 200000 | D13: 2900 | E13: =IF(D13="","",D13*12) -> 34800 | F13: =IF(AND(C13="",D13=""),"leer",IF(OR(C13="",D13=""),"unvollständig",IF(C12="","Lücke",IF(C13<=C12,"nicht aufsteigend","OK")))) -> OK
B14: Stufe 7 | E14: =IF(D14="","",D14*12) | F14: =IF(AND(C14="",D14=""),"leer",IF(OR(C14="",D14=""),"unvollständig",IF(C13="","Lücke",IF(C14<=C13,"nicht aufsteigend","OK")))) -> leer
B15: Stufe 8 | E15: =IF(D15="","",D15*12) | F15: =IF(AND(C15="",D15=""),"leer",IF(OR(C15="",D15=""),"unvollständig",IF(C14="","Lücke",IF(C15<=C14,"nicht aufsteigend","OK")))) -> leer
B16: Stufe 9 | E16: =IF(D16="","",D16*12) | F16: =IF(AND(C16="",D16=""),"leer",IF(OR(C16="",D16=""),"unvollständig",IF(C15="","Lücke",IF(C16<=C15,"nicht aufsteigend","OK")))) -> leer
B17: Stufe 10 | E17: =IF(D17="","",D17*12) | F17: =IF(AND(C17="",D17=""),"leer",IF(OR(C17="",D17=""),"unvollständig",IF(C16="","Lücke",IF(C17<=C16,"nicht aufsteigend","OK")))) -> leer
B18: Darüber (Einkommen über letzter Stufe) | C18: über letzter Stufe | D18: 3100 | E18: =IF(D18="","",D18*12) -> 37200 | F18: =IF(D18="","fehlt","OK") -> OK
B19: Massgebendes Einkommen für die Miete: | C19: ='02 Eingaben'!$C$61 -> Kanton/Gemeinde | D19: Auswahl in 02 Eingaben (Bereich «Planung»). Optionaler Aufschlag dort ebenfalls einstellbar.
B21: 2 Mietstufen-Check (ausgehend von Szenario A – ohne zusätzliche Optimierung)
B22: Einkommen für die Miete (Szenario A) | C22: ='05 Berechnung'!$C$80 -> 177400
B23: Aktuelle Mietstufe (Nr.) | C23: ='05 Berechnung'!$C$81 -> 5
B24: Monatsmiete aktuell | C24: ='05 Berechnung'!$C$82 -> 2700
B25: Obergrenze der nächstniedrigeren Stufe | C25: =IF(C23>1,INDEX('04 Mietmodell'!$C$8:$C$17,C23-1),"keine tiefere Stufe") -> 160000
B26: Zusätzliche Einzahlung nötig, um eine Stufe tiefer zu kommen | C26: =IF(ISNUMBER(C25),MAX(0,C22-C25),"–") -> 17400 | D26: Betrag, um den das steuerbare Einkommen sinken muss (3a oder PK-Einkauf), damit die nächstniedrigere Mietstufe erreicht wird.
B27: Mietersparnis pro Jahr bei Stufenwechsel | C27: =IF(ISNUMBER(C25),(C24-INDEX('04 Mietmodell'!$D$8:$D$17,C23-1))*12,"–") -> 2400
B28: Steuerersparnis dieser Einzahlung (Grenzsteuersatz) | C28: =IF(ISNUMBER(C26),C26*'02 Eingaben'!$C$60,"–") -> 4872
B29: Kombinierter Vorteil pro Jahr (Steuer + Miete) | C29: =IF(ISNUMBER(C26),C27+C28,"–") -> 7272
B31: 3 Was-wäre-wenn: zusätzliche Einzahlung (3a oder PK) auf Szenario A
B32: Zusätzliche Einzahlung (CHF) | C32: 5000
B33: Steuerbares Einkommen für die Miete nach Einzahlung | C33: =MAX(0,C22-C32) -> 172400
B34: Neue Mietstufe (Nr.) | C34: =IF(COUNT('04 Mietmodell'!$C$8:$C$17)=0,0,SUMPRODUCT(('04 Mietmodell'!$C$8:$C$17<>"")*('04 Mietmodell'!$C$8:$C$17<C33))+1) -> 5
B35: Neue Monatsmiete | C35: =IF(COUNT('04 Mietmodell'!$C$8:$C$17)=0,0,IF(C34>COUNT('04 Mietmodell'!$C$8:$C$17),'04 Mietmodell'!$D$18,INDEX('04 Mietmodell'!$D$8:$D$17,C34))) -> 2700
B36: Mietersparnis pro Jahr | C36: =(C24-C35)*12 -> 0
B37: Steuerersparnis (Grenzsteuersatz × Einzahlung) | C37: =C32*'02 Eingaben'!$C$60 -> 1400
B38: Kombinierter Vorteil pro Jahr (Steuer + Miete) | C38: =C36+C37 -> 1400
B39: Ergebnis | C39: =IF(C34<C23,"Mietstufe sinkt von "&C23&" auf "&C34,IF(C34=C23,"Mietstufe bleibt unverändert","Mietstufe steigt")) -> Mietstufe bleibt unverändert
B41: Hinweis: Die Miete hängt am steuerbaren Einkommen – eine zusätzliche Einzahlung wirkt doppelt: Steuerersparnis plus ggf. tiefere Mietstufe. Das gebundene Vorsorgekapital bleibt Ihr Vermögen (3a bzw. PK), ist aber bis zur Pensionierung nicht frei verfügbar.

Sheet 05 Berechnung
B1: 05 Berechnung – detaillierte Logik
B2: Alle Zellen berechnet (geschützt). Änderungen erfolgen in 02 Eingaben, 03 Optimierung und 06 Grundlagen.
B4: 1 Status der Grundlagen
B5: Steuerjahr | C5: ='02 Eingaben'!$C$7 -> 2026
B6: Spaltenindex in 06 Grundlagen (0 = nicht vorhanden) | C6: ='06 Grundlagen'!$C$5 -> 2
B7: Parameter ohne Wert im gewählten Jahr | C7: =COUNTIF('06 Grundlagen'!$L$9:$L$39,0) -> 0
B8: Parameter mit Status «prüfen»/«unsicher» im gewählten Jahr | C8: =SUMPRODUCT(('06 Grundlagen'!$I$9:$I$39<>"")*('06 Grundlagen'!$I$9:$I$39<>"bestätigt")*('06 Grundlagen'!$L$9:$L$39=1)) -> 24
B10: 2 Säule 3a und PK – Potenziale
C11: Ehemann | D11: Ehefrau
B12: Erwerbseinkommen (Basis für 3a-Maximum) | C12: ='02 Eingaben'!$C$21+'02 Eingaben'!$C$22 -> 173000 | D12: ='02 Eingaben'!$D$21+'02 Eingaben'!$D$22 -> 61800
B13: Vorsorgesituation | C13: ='02 Eingaben'!$C$49 -> mit PK | D13: ='02 Eingaben'!$D$49 -> mit PK
B14: 3a-Maximum | C14: =IF(C13="mit PK",'06 Grundlagen'!$D$10,IF(C13="ohne PK",MIN('06 Grundlagen'!$D$11,'06 Grundlagen'!$D$12*MAX(0,C12)),0)) -> 7258 | D14: =IF(D13="mit PK",'06 Grundlagen'!$D$10,IF(D13="ohne PK",MIN('06 Grundlagen'!$D$11,'06 Grundlagen'!$D$12*MAX(0,D12)),0)) -> 7258
B15: 3a bereits geleistet/geplant | C15: =N('02 Eingaben'!$C$50) -> 3000 | D15: =N('02 Eingaben'!$D$50) -> 0
B16: 3a-Potenzial verbleibend | C16: =MAX(0,C14-C15) -> 4258 | D16: =MAX(0,D14-D15) -> 7258
B17: PK-Potenzial erfasst (1 = ja) | C17: =IF('02 Eingaben'!$C$52<>"",1,0) -> 1 | D17: =IF('02 Eingaben'!$D$52<>"",1,0) -> 1
B18: PK-Einkaufspotenzial lt. Vorsorgeausweis | C18: =IF(C17=1,'02 Eingaben'!$C$52,0) -> 40000 | D18: =IF(D17=1,'02 Eingaben'!$D$52,0) -> 15000
B19: PK-Einkauf bereits geleistet/geplant | C19: =N('02 Eingaben'!$C$51) -> 0 | D19: =N('02 Eingaben'!$D$51) -> 0
B20: PK-Potenzial verbleibend (unbegrenzt, falls nicht erfasst) | C20: =IF(C17=1,MAX(0,C18-C19),1000000000) -> 40000 | D20: =IF(D17=1,MAX(0,D18-D19),1000000000) -> 15000
B22: 3 Berufsauslagen (automatisch)
C23: Ehemann Kanton | D23: Ehefrau Kanton | E23: Ehemann Bund | F23: Ehefrau Bund
B24: Massgebender Nettolohn | C24: ='02 Eingaben'!$C$21 -> 173000 | D24: ='02 Eingaben'!$D$21 -> 61800 | E24: ='02 Eingaben'!$C$21 -> 173000 | F24: ='02 Eingaben'!$D$21 -> 61800
B25: Fahrkosten effektiv | C25: =N('02 Eingaben'!$C$28) -> 1800 | D25: =N('02 Eingaben'!$D$28) -> 800 | E25: =N('02 Eingaben'!$C$28) -> 1800 | F25: =N('02 Eingaben'!$D$28) -> 800
B26: Fahrkosten anerkannt (begrenzt) | C26: =MIN(C25,'06 Grundlagen'!$D$20) -> 1800 | D26: =MIN(D25,'06 Grundlagen'!$D$20) -> 800 | E26: =MIN(E25,'06 Grundlagen'!$D$34) -> 1800 | F26: =MIN(F25,'06 Grundlagen'!$D$34) -> 800
B27: Verpflegung (Tage × Satz, begrenzt) | C27: =MIN(N('02 Eingaben'!$C$29)*'06 Grundlagen'!$D$21,'06 Grundlagen'!$D$22) -> 1500 | D27: =MIN(N('02 Eingaben'!$D$29)*'06 Grundlagen'!$D$21,'06 Grundlagen'!$D$22) -> 0 | E27: =MIN(N('02 Eingaben'!$C$29)*'06 Grundlagen'!$D$35,'06 Grundlagen'!$D$36) -> 1500 | F27: =MIN(N('02 Eingaben'!$D$29)*'06 Grundlagen'!$D$35,'06 Grundlagen'!$D$36) -> 0
B28: Übrige Berufsauslagen (Pauschale oder effektiv) | C28: =IF('02 Eingaben'!$C$30<>"",'02 Eingaben'!$C$30,IF(C24>0,MIN('06 Grundlagen'!$D$25,MAX('06 Grundlagen'!$D$24,'06 Grundlagen'!$D$23*C24)),0)) -> 4000 | D28: =IF('02 Eingaben'!$D$30<>"",'02 Eingaben'!$D$30,IF(D24>0,MIN('06 Grundlagen'!$D$25,MAX('06 Grundlagen'!$D$24,'06 Grundlagen'!$D$23*D24)),0)) -> 2000 | E28: =IF('02 Eingaben'!$C$30<>"",'02 Eingaben'!$C$30,IF(E24>0,MIN('06 Grundlagen'!$D$39,MAX('06 Grundlagen'!$D$38,'06 Grundlagen'!$D$37*E24)),0)) -> 4000 | F28: =IF('02 Eingaben'!$D$30<>"",'02 Eingaben'!$D$30,IF(F24>0,MIN('06 Grundlagen'!$D$39,MAX('06 Grundlagen'!$D$38,'06 Grundlagen'!$D$37*F24)),0)) -> 2000
B29: Total Berufsauslagen (automatisch) | C29: =IF(C24>0,SUM(C26:C28),0) -> 7300 | D29: =IF(D24>0,SUM(D26:D28),0) -> 2800 | E29: =IF(E24>0,SUM(E26:E28),0) -> 7300 | F29: =IF(F24>0,SUM(F26:F28),0) -> 2800
B31: 4 Weitere automatische Abzüge
C32: Kanton/Gemeinde | D32: Bund
B33: Maximalabzug Versicherungsprämien (Ehepaar + Kinder) | C33: ='06 Grundlagen'!$D$15+'02 Eingaben'!$C$10*'06 Grundlagen'!$D$16 -> 9700 | D33: ='06 Grundlagen'!$D$28+'02 Eingaben'!$C$10*'06 Grundlagen'!$D$29 -> 5800
B34: Versicherungsabzug (automatisch) | C34: =IF('02 Eingaben'!$C$33="",C33,MIN('02 Eingaben'!$C$33,C33)) -> 9700 | D34: =IF('02 Eingaben'!$C$33="",D33,MIN('02 Eingaben'!$C$33,D33)) -> 5800
B35: Kinderabzug (automatisch) | C35: ='02 Eingaben'!$C$10*'06 Grundlagen'!$D$14 -> 28200 | D35: ='02 Eingaben'!$C$10*'06 Grundlagen'!$D$27 -> 20400
B36: Niedrigeres Erwerbseinkommen nach Berufsauslagen | C36: =MIN('02 Eingaben'!$C$21+'02 Eingaben'!$C$22-C29,'02 Eingaben'!$D$21+'02 Eingaben'!$D$22-D29) -> 59000 | D36: =MIN('02 Eingaben'!$C$21+'02 Eingaben'!$C$22-E29,'02 Eingaben'!$D$21+'02 Eingaben'!$D$22-F29) -> 59000
B37: Zweiverdienerabzug (automatisch) | C37: =IF(AND('02 Eingaben'!$C$8="Verheiratet",'02 Eingaben'!$C$21+'02 Eingaben'!$C$22>0,'02 Eingaben'!$D$21+'02 Eingaben'!$D$22>0),MAX(0,MIN(C36,MAX('06 Grundlagen'!$D$18,MIN('06 Grundlagen'!$D$19,'06 Grundlagen'!$D$17*C36)))),0) -> 5900 | D37: =IF(AND('02 Eingaben'!$C$8="Verheiratet",'02 Eingaben'!$C$21+'02 Eingaben'!$C$22>0,'02 Eingaben'!$D$21+'02 Eingaben'!$D$22>0),MAX(0,MIN(D36,MAX('06 Grundlagen'!$D$31,MIN('06 Grundlagen'!$D$32,'06 Grundlagen'!$D$30*D36)))),0) -> 14100
B38: Verheiratetenabzug (automatisch) | C38: =0 -> 0 | D38: =IF('02 Eingaben'!$C$8="Verheiratet",'06 Grundlagen'!$D$33,0) -> 2800
B40: 5 Steuerbares Einkommen vor Säule 3a / PK-Einkauf
C41: Kanton/Gemeinde | D41: Bund
B42: Total steuerbare Einkünfte | C42: ='02 Eingaben'!$F$24 -> 234800 | D42: ='02 Eingaben'!$F$24 -> 234800
B43: – Berufsauslagen Ehemann | C43: ='02 Eingaben'!$G$35 -> 7300 | D43: ='02 Eingaben'!$H$35 -> 7300
B44: – Berufsauslagen Ehefrau | C44: ='02 Eingaben'!$G$36 -> 2800 | D44: ='02 Eingaben'!$H$36 -> 2800
B45: – Versicherungsprämien/Sparzinsen | C45: ='02 Eingaben'!$G$37 -> 9700 | D45: ='02 Eingaben'!$H$37 -> 5800
...

Sheet 06 Grundlagen
B1: 06 Grundlagen – Steuerjahr, Grenzwerte, Quellen, Annahmen
B2: Alle steuerlichen Werte sind hier zentral erfasst. Jahresspalten in Zeile 8 anpassbar; das Modell greift automatisch auf die Spalte des gewählten Steuerjahrs zu.
B4: Stand der Recherche | C4: 04.10.2026 | J4: WICHTIG: Offizielle Quellen (zh.ch, estv.admin.ch) waren bei der Erstellung technisch nicht direkt abrufbar. Werte wurden über Suchtreffer/Sekundärquellen ermittelt und sind mit Status «prüfen» bzw. «unsicher» markiert. Bitte vor Verwendung mit der Wegleitung zur Steuererklärung ZH und dem Kreisschreiben ESTV abgleichen.
B5: Spaltenindex des gewählten Steuerjahrs (0 = keine Grundlagen für dieses Jahr) | C5: =IFERROR(MATCH('02 Eingaben'!$C$7,$E$8:$H$8,0),0) -> 2 | D5: Steuerjahr gemäss 02 Eingaben: | H5: ='02 Eingaben'!$C$7 -> 2026
B8: Parameter | C8: Ebene | D8: Aktiver Wert (gewähltes Jahr) | E8: 2025 | F8: 2026 | G8: 2027 | H8: 2028 | I8: Status | J8: Quelle | K8: Bemerkung / Annahme | L8: Wert vorhanden
B9: Vorsorge (Bundesrecht, gilt für Kantons- und Bundessteuer)
B10: Säule 3a – Maximalbetrag mit Pensionskasse (kleines 3a) | C10: Bund | D10: =IF($C$5=0,0,IF(INDEX(E10:H10,$C$5)="",0,INDEX(E10:H10,$C$5))) -> 7258 | E10: 7258 | F10: 7258 | I10: bestätigt | J10: BVV 3 (SR 831.461.3) Art. 7; Maximalbeträge 2026 gemäss z. B. https://www.raiffeisen.ch/rch/de/privatkunden/vorsorgen-absichern/maximalbetrag.html | K10: 8 % der oberen BVG-Grenze; für 2025 und 2026 gleich hoch (mehrere Quellen). | L10: =IF($C$5=0,0,IF(INDEX(E10:H10,$C$5)="",0,1)) -> 1
B11: Säule 3a – Maximalbetrag ohne Pensionskasse (grosses 3a) | C11: Bund | D11: =IF($C$5=0,0,IF(INDEX(E11:H11,$C$5)="",0,INDEX(E11:H11,$C$5))) -> 36288 | E11: 36288 | F11: 36288 | I11: bestätigt | J11: BVV 3 (SR 831.461.3) Art. 7; Maximalbeträge 2026 gemäss z. B. https://www.raiffeisen.ch/rch/de/privatkunden/vorsorgen-absichern/maximalbetrag.html | K11: Nur für Personen ohne 2. Säule (z. B. Selbständige). | L11: =IF($C$5=0,0,IF(INDEX(E11:H11,$C$5)="",0,1)) -> 1
B12: Säule 3a ohne PK – maximal Anteil am Nettoerwerbseinkommen | C12: Bund | D12: =IF($C$5=0,0,IF(INDEX(E12:H12,$C$5)="",0,INDEX(E12:H12,$C$5))) -> 0.2 | E12: 0.2 | F12: 0.2 | I12: bestätigt | J12: BVV 3 (SR 831.461.3) Art. 7; Maximalbeträge 2026 gemäss z. B. https://www.raiffeisen.ch/rch/de/privatkunden/vorsorgen-absichern/maximalbetrag.html | K12: Es gilt der kleinere Wert aus Prozentsatz und Maximalbetrag. | L12: =IF($C$5=0,0,IF(INDEX(E12:H12,$C$5)="",0,1)) -> 1
B13: Abzüge Kanton Zürich (Staats- und Gemeindesteuer)
B14: Kinderabzug pro Kind | C14: Kanton | D14: =IF($C$5=0,0,IF(INDEX(E14:H14,$C$5)="",0,INDEX(E14:H14,$C$5))) -> 9400 | E14: 9000 | F14: 9400 | I14: prüfen | J14: Kt. ZH, Weisung der Finanzdirektion über Sozialabzüge und Steuertarife (ab Steuerperiode 2026), ZStB 34.1: https://www.zh.ch/de/steuern-finanzen/steuern/treuhaender/steuerbuch/steuerbuch-definition/zstb-34-1.html | K14: Wert 2026 aus Suchtreffer (CHF 9'400); 2025 CHF 9'000. Bitte in Weisung ZStB 34.1 verifizieren. | L14: =IF($C$5=0,0,IF(INDEX(E14:H14,$C$5)="",0,1)) -> 1
B15: Versicherungsabzug Ehepaar (mit Beiträgen an 2./3. Säule) | C15: Kanton | D15: =IF($C$5=0,0,IF(INDEX(E15:H15,$C$5)="",0,INDEX(E15:H15,$C$5))) -> 5800 | E15: 5800 | F15: 5800 | I15: prüfen | J15: Kt. ZH, Wegleitung zur Steuererklärung 2025/2026: https://www.zh.ch/de/steuern-finanzen/steuern/steuern-natuerliche-personen/steuerwissen-natuerliche-personen.html | K15: Wegleitung Ziff. «Versicherungsprämien und Sparzinsen». Ohne Vorsorgebeiträge gilt ein tieferer Betrag. | L15: =IF($C$5=0,0,IF(INDEX(E15:H15,$C$5)="",0,1)) -> 1
B16: Versicherungsabzug zusätzlich pro Kind | C16: Kanton | D16: =IF($C$5=0,0,IF(INDEX(E16:H16,$C$5)="",0,INDEX(E16:H16,$C$5))) -> 1300 | E16: 1300 | F16: 1300 | I16: bestätigt | J16: Kt. ZH, Wegleitung zur Steuererklärung 2025/2026: https://www.zh.ch/de/steuern-finanzen/steuern/steuern-natuerliche-personen/steuerwissen-natuerliche-personen.html | K16: CHF 1'300 je Kind/unterstützte Person (Wegleitung 2025 und 2026). | L16: =IF($C$5=0,0,IF(INDEX(E16:H16,$C$5)="",0,1)) -> 1
B17: Zweiverdienerabzug – Prozentsatz des niedrigeren Erwerbseinkommens | C17: Kanton | D17: =IF($C$5=0,0,IF(INDEX(E17:H17,$C$5)="",0,INDEX(E17:H17,$C$5))) -> 0.5 | E17: 0.5 | F17: 0.5 | I17: unsicher | J17: Kt. ZH, Wegleitung zur Steuererklärung 2025/2026: https://www.zh.ch/de/steuern-finanzen/steuern/steuern-natuerliche-personen/steuerwissen-natuerliche-personen.html | K17: UNSICHER: Suchtreffer widersprüchlich (CHF 5'900 vs. 8'100–13'400). Regel und Beträge in der Wegleitung prüfen; sonst in 02 Eingaben manuell überschreiben. | L17: =IF($C$5=0,0,IF(INDEX(E17:H17,$C$5)="",0,1)) -> 1
B18: Zweiverdienerabzug – Minimum | C18: Kanton | D18: =IF($C$5=0,0,IF(INDEX(E18:H18,$C$5)="",0,INDEX(E18:H18,$C$5))) -> 0 | E18: 0 | F18: 0 | I18: unsicher | J18: Kt. ZH, Wegleitung zur Steuererklärung 2025/2026: https://www.zh.ch/de/steuern-finanzen/steuern/steuern-natuerliche-personen/steuerwissen-natuerliche-personen.html | K18: Siehe oben – manuell zu verifizieren. | L18: =IF($C$5=0,0,IF(INDEX(E18:H18,$C$5)="",0,1)) -> 1
B19: Zweiverdienerabzug – Maximum | C19: Kanton | D19: =IF($C$5=0,0,IF(INDEX(E19:H19,$C$5)="",0,INDEX(E19:H19,$C$5))) -> 5900 | E19: 5900 | F19: 5900 | I19: unsicher | J19: Kt. ZH, Wegleitung zur Steuererklärung 2025/2026: https://www.zh.ch/de/steuern-finanzen/steuern/steuern-natuerliche-personen/steuerwissen-natuerliche-personen.html | K19: Suchtreffer: CHF 5'900 (Kantons-/Gemeindesteuer). Bitte verifizieren. | L19: =IF($C$5=0,0,IF(INDEX(E19:H19,$C$5)="",0,1)) -> 1
B20: Berufsauslagen – Fahrkosten Arbeitsweg, Maximalabzug | C20: Kanton | D20: =IF($C$5=0,0,IF(INDEX(E20:H20,$C$5)="",0,INDEX(E20:H20,$C$5))) -> 5200 | E20: 5200 | F20: 5200 | I20: prüfen | J20: Kt. ZH, Verfügung der Finanzdirektion über die Pauschalierung von Berufsauslagen (ab Steuerperiode 2026), ZStB 26.1: https://www.zh.ch/de/steuern-finanzen/steuern/treuhaender/steuerbuch/steuerbuch-definition/zstb-26-1.html | K20: Suchtreffer: CHF 5'200 (2025/2026). Bitte verifizieren. | L20: =IF($C$5=0,0,IF(INDEX(E20:H20,$C$5)="",0,1)) -> 1
B21: Berufsauslagen – Verpflegung pro Arbeitstag auswärts | C21: Kanton | D21: =IF($C$5=0,0,IF(INDEX(E21:H21,$C$5)="",0,INDEX(E21:H21,$C$5))) -> 15 | E21: 15 | F21: 15 | I21: prüfen | J21: Kt. ZH, Verfügung der Finanzdirektion über die Pauschalierung von Berufsauslagen (ab Steuerperiode 2026), ZStB 26.1: https://www.zh.ch/de/steuern-finanzen/steuern/treuhaender/steuerbuch/steuerbuch-definition/zstb-26-1.html | K21: CHF 15 pro Tag. | L21: =IF($C$5=0,0,IF(INDEX(E21:H21,$C$5)="",0,1)) -> 1
B22: Berufsauslagen – Verpflegung, Maximum pro Jahr | C22: Kanton | D22: =IF($C$5=0,0,IF(INDEX(E22:H22,$C$5)="",0,INDEX(E22:H22,$C$5))) -> 3200 | E22: 3200 | F22: 3200 | I22: prüfen | J22: Kt. ZH, Verfügung der Finanzdirektion über die Pauschalierung von Berufsauslagen (ab Steuerperiode 2026), ZStB 26.1: https://www.zh.ch/de/steuern-finanzen/steuern/treuhaender/steuerbuch/steuerbuch-definition/zstb-26-1.html | K22: CHF 3'200 pro Jahr. | L22: =IF($C$5=0,0,IF(INDEX(E22:H22,$C$5)="",0,1)) -> 1
B23: Übrige Berufsauslagen – Pauschale in % des Nettolohns | C23: Kanton | D23: =IF($C$5=0,0,IF(INDEX(E23:H23,$C$5)="",0,INDEX(E23:H23,$C$5))) -> 0.03 | E23: 0.03 | F23: 0.03 | I23: prüfen | J23: Kt. ZH, Verfügung der Finanzdirektion über die Pauschalierung von Berufsauslagen (ab Steuerperiode 2026), ZStB 26.1: https://www.zh.ch/de/steuern-finanzen/steuern/treuhaender/steuerbuch/steuerbuch-definition/zstb-26-1.html | K23: 3 % des Nettolohns (Ziff. 11 Lohnausweis). | L23: =IF($C$5=0,0,IF(INDEX(E23:H23,$C$5)="",0,1)) -> 1
B24: Übrige Berufsauslagen – Pauschale Minimum | C24: Kanton | D24: =IF($C$5=0,0,IF(INDEX(E24:H24,$C$5)="",0,INDEX(E24:H24,$C$5))) -> 2000 | E24: 2000 | F24: 2000 | I24: prüfen | J24: Kt. ZH, Verfügung der Finanzdirektion über die Pauschalierung von Berufsauslagen (ab Steuerperiode 2026), ZStB 26.1: https://www.zh.ch/de/steuern-finanzen/steuern/treuhaender/steuerbuch/steuerbuch-definition/zstb-26-1.html | L24: =IF($C$5=0,0,IF(INDEX(E24:H24,$C$5)="",0,1)) -> 1
B25: Übrige Berufsauslagen – Pauschale Maximum | C25: Kanton | D25: =IF($C$5=0,0,IF(INDEX(E25:H25,$C$5)="",0,INDEX(E25:H25,$C$5))) -> 4000 | E25: 4000 | F25: 4000 | I25: prüfen | J25: Kt. ZH, Verfügung der Finanzdirektion über die Pauschalierung von Berufsauslagen (ab Steuerperiode 2026), ZStB 26.1: https://www.zh.ch/de/steuern-finanzen/steuern/treuhaender/steuerbuch/steuerbuch-definition/zstb-26-1.html | L25: =IF($C$5=0,0,IF(INDEX(E25:H25,$C$5)="",0,1)) -> 1
B26: Abzüge direkte Bundessteuer (DBG)
B27: Kinderabzug pro Kind | C27: Bund | D27: =IF($C$5=0,0,IF(INDEX(E27:H27,$C$5)="",0,INDEX(E27:H27,$C$5))) -> 6800 | E27: 6800 | F27: 6800 | I27: prüfen | J27: ESTV, Kreisschreiben/Teuerungsausgleich DBG (Familienbesteuerung, Stand 1.1.2026): https://www.estv2.admin.ch/stp/ds/f-familienbesteuerung-de.pdf | K27: CHF 6'800 (Reform Individualbesteuerung später: CHF 12'000, aufgeteilt – für 2026 nicht relevant). | L27: =IF($C$5=0,0,IF(INDEX(E27:H27,$C$5)="",0,1)) -> 1
B28: Versicherungsabzug Ehepaar (mit Beiträgen an 2./3. Säule) | C28: Bund | D28: =IF($C$5=0,0,IF(INDEX(E28:H28,$C$5)="",0,INDEX(E28:H28,$C$5))) -> 3700 | F28: 3700 | I28: prüfen | J28: ESTV, Kreisschreiben/Teuerungsausgleich DBG (Familienbesteuerung, Stand 1.1.2026): https://www.estv2.admin.ch/stp/ds/f-familienbesteuerung-de.pdf | K28: 2025 nicht verifiziert → leer gelassen. | L28: =IF($C$5=0,0,IF(INDEX(E28:H28,$C$5)="",0,1)) -> 1
B29: Versicherungsabzug zusätzlich pro Kind | C29: Bund | D29: =IF($C$5=0,0,IF(INDEX(E29:H29,$C$5)="",0,INDEX(E29:H29,$C$5))) -> 700 | F29: 700 | I29: prüfen | J29: ESTV, Kreisschreiben/Teuerungsausgleich DBG (Familienbesteuerung, Stand 1.1.2026): https://www.estv2.admin.ch/stp/ds/f-familienbesteuerung-de.pdf | K29: 2025 nicht verifiziert → leer gelassen. | L29: =IF($C$5=0,0,IF(INDEX(E29:H29,$C$5)="",0,1)) -> 1
B30: Zweiverdienerabzug – Prozentsatz des niedrigeren Erwerbseinkommens | C30: Bund | D30: =IF($C$5=0,0,IF(INDEX(E30:H30,$C$5)="",0,INDEX(E30:H30,$C$5))) -> 0.5 | E30: 0.5 | F30: 0.5 | I30: prüfen | J30: ESTV, Kreisschreiben/Teuerungsausgleich DBG (Familienbesteuerung, Stand 1.1.2026): https://www.estv2.admin.ch/stp/ds/f-familienbesteuerung-de.pdf | K30: Art. 33 Abs. 2 DBG: 50 % des niedrigeren Einkommens. | L30: =IF($C$5=0,0,IF(INDEX(E30:H30,$C$5)="",0,1)) -> 1
B31: Zweiverdienerabzug – Minimum | C31: Bund | D31: =IF($C$5=0,0,IF(INDEX(E31:H31,$C$5)="",0,INDEX(E31:H31,$C$5))) -> 8600 | F31: 8600 | I31: prüfen | J31: ESTV, Kreisschreiben/Teuerungsausgleich DBG (Familienbesteuerung, Stand 1.1.2026): https://www.estv2.admin.ch/stp/ds/f-familienbesteuerung-de.pdf | K31: 2025 nicht verifiziert → leer gelassen. | L31: =IF($C$5=0,0,IF(INDEX(E31:H31,$C$5)="",0,1)) -> 1
B32: Zweiverdienerabzug – Maximum | C32: Bund | D32: =IF($C$5=0,0,IF(INDEX(E32:H32,$C$5)="",0,INDEX(E32:H32,$C$5))) -> 14100 | F32: 14100 | I32: prüfen | J32: ESTV, Kreisschreiben/Teuerungsausgleich DBG (Familienbesteuerung, Stand 1.1.2026): https://www.estv2.admin.ch/stp/ds/f-familienbesteuerung-de.pdf | K32: 2025 nicht verifiziert → leer gelassen. | L32: =IF($C$5=0,0,IF(INDEX(E32:H32,$C$5)="",0,1)) -> 1
B33: Verheiratetenabzug | C33: Bund | D33: =IF($C$5=0,0,IF(INDEX(E33:H33,$C$5)="",0,INDEX(E33:H33,$C$5))) -> 2800 | E33: 2800 | F33: 2800 | I33: prüfen | J33: ESTV, Kreisschreiben/Teuerungsausgleich DBG (Familienbesteuerung, Stand 1.1.2026): https://www.estv2.admin.ch/stp/ds/f-familienbesteuerung-de.pdf | K33: Nur direkte Bundessteuer; im Kanton Zürich kein gleichwertiger Abzug (dort Tarif/Splitting). | L33: =IF($C$5=0,0,IF(INDEX(E33:H33,$C$5)="",0,1)) -> 1
B34: Berufsauslagen – Fahrkosten Arbeitsweg, Maximalabzug | C34: Bund | D34: =IF($C$5=0,0,IF(INDEX(E34:H34,$C$5)="",0,INDEX(E34:H34,$C$5))) -> 3300 | E34: 3200 | F34: 3300 | I34: prüfen | J34: ESTV, Kreisschreiben/Teuerungsausgleich DBG (Familienbesteuerung, Stand 1.1.2026): https://www.estv2.admin.ch/stp/ds/f-familienbesteuerung-de.pdf | K34: Teuerungsanpassung 2026: CHF 3'300 (Suchtreffer). | L34: =IF($C$5=0,0,IF(INDEX(E34:H34,$C$5)="",0,1)) -> 1
B35: Berufsauslagen – Verpflegung pro Arbeitstag auswärts | C35: Bund | D35: =IF($C$5=0,0,IF(INDEX(E35:H35,$C$5)="",0,INDEX(E35:H35,$C$5))) -> 15 | E35: 15 | F35: 15 | I35: prüfen | J35: ESTV, Kreisschreiben/Teuerungsausgleich DBG (Familienbesteuerung, Stand 1.1.2026): https://www.estv2.admin.ch/stp/ds/f-familienbesteuerung-de.pdf | L35: =IF($C$5=0,0,IF(INDEX(E35:H35,$C$5)="",0,1)) -> 1
B36: Berufsauslagen – Verpflegung, Maximum pro Jahr | C36: Bund | D36: =IF($C$5=0,0,IF(INDEX(E36:H36,$C$5)="",0,INDEX(E36:H36,$C$5))) -> 3200 | E36: 3200 | F36: 3200 | I36: prüfen | J36: ESTV, Kreisschreiben/Teuerungsausgleich DBG (Familienbesteuerung, Stand 1.1.2026): https://www.estv2.admin.ch/stp/ds/f-familienbesteuerung-de.pdf | L36: =IF($C$5=0,0,IF(INDEX(E36:H36,$C$5)="",0,1)) -> 1
B37: Übrige Berufsauslagen – Pauschale in % des Nettolohns | C37: Bund | D37: =IF($C$5=0,0,IF(INDEX(E37:H37,$C$5)="",0,INDEX(E37:H37,$C$5))) -> 0.03 | E37: 0.03 | F37: 0.03 | I37: prüfen | J37: ESTV, Kreisschreiben/Teuerungsausgleich DBG (Familienbesteuerung, Stand 1.1.2026): https://www.estv2.admin.ch/stp/ds/f-familienbesteuerung-de.pdf | L37: =IF($C$5=0,0,IF(INDEX(E37:H37,$C$5)="",0,1)) -> 1
B38: Übrige Berufsauslagen – Pauschale Minimum | C38: Bund | D38: =IF($C$5=0,0,IF(INDEX(E38:H38,$C$5)="",0,INDEX(E38:H38,$C$5))) -> 2000 | E38: 2000 | F38: 2000 | I38: prüfen | J38: ESTV, Kreisschreiben/Teuerungsausgleich DBG (Familienbesteuerung, Stand 1.1.2026): https://www.estv2.admin.ch/stp/ds/f-familienbesteuerung-de.pdf | L38: =IF($C$5=0,0,IF(INDEX(E38:H38,$C$5)="",0,1)) -> 1
B39: Übrige Berufsauslagen – Pauschale Maximum | C39: Bund | D39: =IF($C$5=0,0,IF(INDEX(E39:H39,$C$5)="",0,INDEX(E39:H39,$C$5))) -> 4000 | E39: 4000 | F39: 4000 | I39: prüfen | J39: ESTV, Kreisschreiben/Teuerungsausgleich DBG (Familienbesteuerung, Stand 1.1.2026): https://www.estv2.admin.ch/stp/ds/f-familienbesteuerung-de.pdf | L39: =IF($C$5=0,0,IF(INDEX(E39:H39,$C$5)="",0,1)) -> 1
B41: Rechtliche Hinweise, Annahmen und Unsicherheiten
B42: 1. Säule 3a: Abzugsfähig sind Einzahlungen des Steuerjahres (tatsächliche Gutschrift bis 31.12.) bis zum Maximalbetrag; Ehegatten beanspruchen den Abzug je einzeln, sofern beide erwerbstätig sind und ein eigenes 3a-Konto haben.
B43: 2. Freiwillige PK-Einkäufe: In Kantons- und Bundessteuer voll abziehbar, soweit Einkaufspotenzial gemäss Vorsorgeausweis besteht. Nach einem Einkauf gilt eine Sperrfrist von 3 Jahren für Kapitalbezüge (Art. 79b Abs. 3 BVG). Das Modell bildet nur den steuerlichen Effekt ab.
B44: 3. Steuerbares Einkommen Kanton/Gemeinde und direkte Bundessteuer unterscheiden sich durch teils abweichende Abzüge (Kinder, Versicherung, Zweiverdiener, Verheiratetenabzug, Fahrkosten). Beide werden getrennt berechnet; Ziel und Miete beziehen sich standardmässig auf Kanton/Gemeinde (einstellbar).
...

Sheet 07 Vorjahre
B1: 07 Vorjahre – Referenzdaten 2023 bis 2025
B2: Gelb = Eingabe. Das steuerbare Einkommen des Referenzjahres dient als Referenzwert (Auswahl in 02 Eingaben). Beispielwerte bitte überschreiben.
B5: Jahr | C5: Steuerbares Einkommen Kanton/Gemeinde | D5: Steuerbares Einkommen Bund (optional) | E5: 3a Ehemann effektiv | F5: 3a Ehefrau effektiv | G5: PK-Einkauf Ehemann | H5: PK-Einkauf Ehefrau | I5: Total Vorsorge (berechnet) | J5: Bezahlte Steuern (optional) | K5: Monatsmiete (optional) | L5: Monatsmiete lt. Mietmodell (berechnet) | M5: Verwendete Monatsmiete | N5: Jahresmiete | O5: 3a-Maximum (Referenz)
B6: 2023 | C6: 172000 | E6: 7056 | F6: 7056 | G6: 0 | H6: 0 | I6: =SUM(E6:H6) -> 14112 | L6: =IF(OR(C6="",COUNT('04 Mietmodell'!$C$8:$C$17)=0),"",IF(SUMPRODUCT(('04 Mietmodell'!$C$8:$C$17<>"")*('04 Mietmodell'!$C$8:$C$17<C6))+1>COUNT('04 Mietmodell'!$C$8:$C$17),'04 Mietmodell'!$D$18,INDEX('04 Mietmodell'!$D$8:$D$17,SUMPRODUCT(('04 Mietmodell'!$C$8:$C$17<>"")*('04 Mietmodell'!$C$8:$C$17<C6))+1))) -> 2700 | M6: =IF(K6<>"",K6,L6) -> 2700 | N6: =IF(ISNUMBER(M6),M6*12,"") -> 32400 | O6: 7056
B7: 2024 | C7: 168500 | E7: 7056 | F7: 7056 | G7: 5000 | H7: 0 | I7: =SUM(E7:H7) -> 19112 | L7: =IF(OR(C7="",COUNT('04 Mietmodell'!$C$8:$C$17)=0),"",IF(SUMPRODUCT(('04 Mietmodell'!$C$8:$C$17<>"")*('04 Mietmodell'!$C$8:$C$17<C7))+1>COUNT('04 Mietmodell'!$C$8:$C$17),'04 Mietmodell'!$D$18,INDEX('04 Mietmodell'!$D$8:$D$17,SUMPRODUCT(('04 Mietmodell'!$C$8:$C$17<>"")*('04 Mietmodell'!$C$8:$C$17<C7))+1))) -> 2700 | M7: =IF(K7<>"",K7,L7) -> 2700 | N7: =IF(ISNUMBER(M7),M7*12,"") -> 32400 | O7: 7056
B8: 2025 | C8: 165000 | E8: 7258 | F8: 7258 | G8: 5000 | H8: 0 | I8: =SUM(E8:H8) -> 19516 | J8: 31000 | K8: 2500 | L8: =IF(OR(C8="",COUNT('04 Mietmodell'!$C$8:$C$17)=0),"",IF(SUMPRODUCT(('04 Mietmodell'!$C$8:$C$17<>"")*('04 Mietmodell'!$C$8:$C$17<C8))+1>COUNT('04 Mietmodell'!$C$8:$C$17),'04 Mietmodell'!$D$18,INDEX('04 Mietmodell'!$D$8:$D$17,SUMPRODUCT(('04 Mietmodell'!$C$8:$C$17<>"")*('04 Mietmodell'!$C$8:$C$17<C8))+1))) -> 2700 | M8: =IF(K8<>"",K8,L8) -> 2500 | N8: =IF(ISNUMBER(M8),M8*12,"") -> 30000 | O8: 7258
B9: 2026 | I9: =SUM(E9:H9) -> 0 | L9: =IF(OR(C9="",COUNT('04 Mietmodell'!$C$8:$C$17)=0),"",IF(SUMPRODUCT(('04 Mietmodell'!$C$8:$C$17<>"")*('04 Mietmodell'!$C$8:$C$17<C9))+1>COUNT('04 Mietmodell'!$C$8:$C$17),'04 Mietmodell'!$D$18,INDEX('04 Mietmodell'!$D$8:$D$17,SUMPRODUCT(('04 Mietmodell'!$C$8:$C$17<>"")*('04 Mietmodell'!$C$8:$C$17<C9))+1))) | M9: =IF(K9<>"",K9,L9) | N9: =IF(ISNUMBER(M9),M9*12,"") | O9: 7258
B11: Zeile 2026 (Reserve): wird nach Jahresende zum neuen Vorjahr. Jahreszahlen in Spalte B sind anpassbar. 3a-Maximum 2023/2024: CHF 7'056, 2025: CHF 7'258 (BVV 3). Miete lt. Mietmodell dient als Ersatz, falls keine effektive Miete erfasst ist.
